#VRML_SIM R2019a utf8
WorldInfo {
}
Viewpoint {
  orientation -0.9997765956731626 -0.02034246210566557 -0.005739597517351579 0.5501167947572834
  position -0.011595241063120846 0.6367205018795787 0.5863907384686188
}
TexturedBackground {
}
TexturedBackgroundLight {
}
Floor {
}
DEF PYRAMID Solid {
  children [
    Group {
    }
    Transform {
      translation 0 0.03 0
      rotation 0 0 1 -1.5708003061004252
      children [
        Shape {
          appearance DEF A_CYLINDER PBRAppearance {
            baseColor 0.6431372549019608 0 0
          }
          geometry DEF G_CYLINDER Cylinder {
            height 0.22
            radius 0.02
          }
        }
        Transform {
          translation 0 0.15 0
          children [
            Shape {
              appearance DEF A_SPHERE PBRAppearance {
                baseColor 0.20392156862745098 0.396078431372549 0.6431372549019608
              }
              geometry DEF G_SPHERE Sphere {
                radius 0.05
              }
            }
            Transform {
              translation 0 -0.3 0
              children [
                Shape {
                  appearance USE A_SPHERE
                  geometry USE G_SPHERE
                }
                Transform {
                  translation 0 0.09 -0.125
                  rotation 1 0 0 2.1728996938995744
                  children [
                    Shape {
                      appearance USE A_CYLINDER
                      geometry USE G_CYLINDER
                    }
                    Transform {
                      translation 0 -0.11 0
                      children [
                        Shape {
                          appearance USE A_SPHERE
                          geometry Sphere {
                            radius 0.05
                          }
                        }
                        Transform {
                          translation 0 0.05 -0.12
                          rotation 1 0 0 -1.15
                          children [
                            Shape {
                              appearance USE A_CYLINDER
                              geometry USE G_CYLINDER
                            }
                            Transform {
                              translation -0.12 0.05 0.04
                              rotation 0.5773502691896258 0.5773502691896258 0.5773502691896258 4.974189693899574
                              children [
                                Shape {
                                  appearance USE A_CYLINDER
                                  geometry USE G_CYLINDER
                                }
                                Transform {
                                  translation 0 -0.11 0
                                  children [
                                    Shape {
                                      appearance USE A_SPHERE
                                      geometry USE G_SPHERE
                                    }
                                    Transform {
                                      translation 0.135511 0.052627031215112224 0.003
                                      rotation 0.3646475979273518 0.5591453478824062 0.7445727696251557 4.79
                                      children [
                                        Shape {
                                          appearance USE A_CYLINDER
                                          geometry USE G_CYLINDER
                                        }
                                        Transform {
                                          translation -0.099 -0.0955 -0.03
                                          rotation -0.07880224848750886 -0.23036375022130823 0.9699086287982428 1.2
                                          children [
                                            Shape {
                                              appearance USE A_CYLINDER
                                              geometry USE G_CYLINDER
                                            }
                                          ]
                                        }
                                      ]
                                    }
                                  ]
                                }
                              ]
                            }
                          ]
                        }
                      ]
                    }
                  ]
                }
              ]
            }
          ]
        }
      ]
    }
  ]
  boundingObject Cylinder {
    height 0.22
    radius 0.02
  }
}
Solid {
  translation 0.005 0.27 -0.075
  children [
    Shape {
      appearance PBRAppearance {
        baseColor 0.9607843137254902 0.4745098039215686 0
      }
      geometry Box {
        size 0.05 0.05 0.05
      }
    }
    HingeJoint {
      jointParameters HingeJointParameters {
        axis 0 1 0
        anchor 0 0.03 0
      }
      endPoint Solid {
        translation 0 0.03 0
        children [
          Group {
            children [
              Transform {
                children [
                  Shape {
                    appearance DEF A_MILL PBRAppearance {
                      baseColor 0.9294117647058824 0.8313725490196079 0
                    }
                    geometry DEF G_MILL Box {
                      size 0.4 0.01 0.05
                    }
                  }
                  Transform {
                    rotation 0 1 0 1.5707996938995747
                    children [
                      Shape {
                        appearance USE A_MILL
                        geometry USE G_MILL
                      }
                    ]
                  }
                ]
              }
            ]
          }
          HingeJoint {
            jointParameters HingeJointParameters {
              axis 0 0 1
              anchor 0.2 0 0
            }
            endPoint Solid {
              translation 0.225 0 0
              rotation 0 0 1 0
              children [
                Shape {
                  appearance DEF A_MINI_BOX PBRAppearance {
                    baseColor 0.3058823529411765 0.6039215686274509 0.023529411764705882
                  }
                  geometry DEF G_MINI_BOX Box {
                    size 0.049999999999999996 0.01 0.05
                  }
                }
              ]
              boundingObject USE G_MINI_BOX
              physics Physics {
              }
            }
          }
        ]
        boundingObject Box {
          size 0.4 0.01 0.05
        }
        physics Physics {
        }
      }
    }
  ]
  name "solid(1)"
  boundingObject Box {
    size 0.05 0.05 0.05
  }
}
